Workbook

Sheet Assumptions
A1: Revenue forecast – assumptions
A2: Blue = editable inputs. All are estimates, not verified benchmarks, unless the note cites a source. Change them and the Forecast tab updates.
A4: Driver | B4: Low | C4: Base | D4: High | E4: Note / source
A5: Impressions multiplier vs base path | B5: 0.4 | C5: 1 | D5: 2.5 | E5: Scales the monthly impressions path below. Estimate – first pins showed 6–8 views each after ~2 days (Pinterest, 12 Oct 2026).
A6: Outbound click rate (impressions → site visits) | B6: 0.003 | C6: 0.006 | D6: 0.01 | E6: Estimate – no verified Pinterest benchmark used.
A7: Site visit → affiliate link click | B7: 0.15 | C7: 0.25 | D7: 0.35 | E7: Estimate.
A8: Amazon conversion (click → order) | B8: 0.03 | C8: 0.05 | D8: 0.08 | E8: Estimate – Amazon's own conversion not published to us.
A9: Amazon average basket (£) | B9: 25 | C9: 35 | D9: 45 | E9: Estimate – mix of cheap renter items and occasional bigger buys.
A10: Amazon commission rate | B10: 0.025 | C10: 0.03 | D10: 0.04 | E10: Estimate – check Amazon UK Associates fee schedule for home/kitchen rates.
A11: Awin conversion (click → order) | B11: 0.014 | C11: 0.02 | D11: 0.03 | E11: Awin directory conversion rates seen 12 Oct 2026: Meaco 1.44%, Ebac 1.51%, AO 2.02%, Currys 2.99%.
A12: Awin average order (£) | B12: 80 | C12: 110 | D12: 150 | E12: Estimate – airers £55–£160, dehumidifiers £140–£350 (Which?, Oct 2026).
A13: Awin commission rate (blended) | B13: 0.025 | C13: 0.035 | D13: 0.045 | E13: From retailer terms: Ebac 5%, Meaco 4%, Beldray 5%, Lakeland 2.5%, The Range 2%.
A14: Tailwind cost (£/month) | B14: 23 | C14: 23 | D14: 23 | E14: $29.99/month plan; £ figure approximate – check your statement.
A17: Monthly path (base case)
A18: Month | B18: Base impressions | C18: Share of clicks to Awin retailers | D18: Seasonality (conversion) | E18: Note
A19: Oct 2026 | B19: 2000 | C19: 0 | D19: 1 | E19: Part month; 19 photo pins live from 12 Oct
A20: Nov 2026 | B20: 12000 | C20: 0.3 | D20: 1.1 | E20: First Awin approvals assumed mid-month
A21: Dec 2026 | B21: 30000 | C21: 0.5 | D21: 1.3 | E21: Christmas gifting peak
A22: Jan 2027 | B22: 28000 | C22: 0.5 | D22: 0.9 | E22: Post-Christmas dip; winter warmth/damp guides strong
A23: Feb 2027 | B23: 38000 | C23: 0.5 | D23: 0.9
A24: Mar 2027 | B24: 50000 | C24: 0.5 | D24: 1 | E24: ~150 pins/month cumulative

Sheet Forecast
A1: Six-month revenue forecast (commission earned, before payout delays)
A2: Earned ≠ received: Amazon and Awin pay weeks to months later (Awin average payment times 57–144 days for our retailers).
A4: Low case | B4: =Assumptions!A19 -> Oct 2026 | C4: =Assumptions!A20 -> Nov 2026 | D4: =Assumptions!A21 -> Dec 2026 | E4: =Assumptions!A22 -> Jan 2027 | F4: =Assumptions!A23 -> Feb 2027 | G4: =Assumptions!A24 -> Mar 2027 | H4: Total
A5: Pin impressions | B5: =Assumptions!B19*Assumptions!$B$5 -> 800 | C5: =Assumptions!B20*Assumptions!$B$5 -> 4800 | D5: =Assumptions!B21*Assumptions!$B$5 -> 12000 | E5: =Assumptions!B22*Assumptions!$B$5 -> 11200 | F5: =Assumptions!B23*Assumptions!$B$5 -> 15200 | G5: =Assumptions!B24*Assumptions!$B$5 -> 20000 | H5: =SUM(B5:G5) -> 64000
A6: Site visits | B6: =B5*Assumptions!$B$6 -> 2.4 | C6: =C5*Assumptions!$B$6 -> 14.4 | D6: =D5*Assumptions!$B$6 -> 36 | E6: =E5*Assumptions!$B$6 -> 33.6 | F6: =F5*Assumptions!$B$6 -> 45.6 | G6: =G5*Assumptions!$B$6 -> 60 | H6: =SUM(B6:G6) -> 192
A7: Affiliate clicks | B7: =B6*Assumptions!$B$7 -> 0.36 | C7: =C6*Assumptions!$B$7 -> 2.16 | D7: =D6*Assumptions!$B$7 -> 5.4 | E7: =E6*Assumptions!$B$7 -> 5.04 | F7: =F6*Assumptions!$B$7 -> 6.84 | G7: =G6*Assumptions!$B$7 -> 9 | H7: =SUM(B7:G7) -> 28.8
A8: Amazon clicks | B8: =B7*(1-Assumptions!C19) -> 0.36 | C8: =C7*(1-Assumptions!C20) -> 1.512 | D8: =D7*(1-Assumptions!C21) -> 2.7 | E8: =E7*(1-Assumptions!C22) -> 2.52 | F8: =F7*(1-Assumptions!C23) -> 3.42 | G8: =G7*(1-Assumptions!C24) -> 4.5 | H8: =SUM(B8:G8) -> 15.012
A9: Amazon orders | B9: =B8*Assumptions!$B$8*Assumptions!D19 -> 0.0108 | C9: =C8*Assumptions!$B$8*Assumptions!D20 -> 0.049896 | D9: =D8*Assumptions!$B$8*Assumptions!D21 -> 0.1053 | E9: =E8*Assumptions!$B$8*Assumptions!D22 -> 0.06804 | F9: =F8*Assumptions!$B$8*Assumptions!D23 -> 0.09234 | G9: =G8*Assumptions!$B$8*Assumptions!D24 -> 0.135 | H9: =SUM(B9:G9) -> 0.461376
A10: Amazon commission (£) | B10: =B9*Assumptions!$B$9*Assumptions!$B$10 -> 0.00675 | C10: =C9*Assumptions!$B$9*Assumptions!$B$10 -> 0.031185 | D10: =D9*Assumptions!$B$9*Assumptions!$B$10 -> 0.0658125 | E10: =E9*Assumptions!$B$9*Assumptions!$B$10 -> 0.042525 | F10: =F9*Assumptions!$B$9*Assumptions!$B$10 -> 0.0577125 | G10: =G9*Assumptions!$B$9*Assumptions!$B$10 -> 0.084375 | H10: =SUM(B10:G10) -> 0.28836
A11: Awin clicks | B11: =B7*Assumptions!C19 -> 0 | C11: =C7*Assumptions!C20 -> 0.648 | D11: =D7*Assumptions!C21 -> 2.7 | E11: =E7*Assumptions!C22 -> 2.52 | F11: =F7*Assumptions!C23 -> 3.42 | G11: =G7*Assumptions!C24 -> 4.5 | H11: =SUM(B11:G11) -> 13.788
A12: Awin orders | B12: =B11*Assumptions!$B$11*Assumptions!D19 -> 0 | C12: =C11*Assumptions!$B$11*Assumptions!D20 -> 0.0099792 | D12: =D11*Assumptions!$B$11*Assumptions!D21 -> 0.04914 | E12: =E11*Assumptions!$B$11*Assumptions!D22 -> 0.031752 | F12: =F11*Assumptions!$B$11*Assumptions!D23 -> 0.043092 | G12: =G11*Assumptions!$B$11*Assumptions!D24 -> 0.063 | H12: =SUM(B12:G12) -> 0.1969632
A13: Awin commission (£) | B13: =B12*Assumptions!$B$12*Assumptions!$B$13 -> 0 | C13: =C12*Assumptions!$B$12*Assumptions!$B$13 -> 0.0199584 | D13: =D12*Assumptions!$B$12*Assumptions!$B$13 -> 0.09828 | E13: =E12*Assumptions!$B$12*Assumptions!$B$13 -> 0.063504 | F13: =F12*Assumptions!$B$12*Assumptions!$B$13 -> 0.086184 | G13: =G12*Assumptions!$B$12*Assumptions!$B$13 -> 0.126 | H13: =SUM(B13:G13) -> 0.3939264
A14: Total commission (£) | B14: =B10+B13 -> 0.00675 | C14: =C10+C13 -> 0.0511434 | D14: =D10+D13 -> 0.1640925 | E14: =E10+E13 -> 0.106029 | F14: =F10+F13 -> 0.1438965 | G14: =G10+G13 -> 0.210375 | H14: =SUM(B14:G14) -> 0.6822864
A15: Tailwind cost (£) | B15: =Assumptions!$B$14 -> 23 | C15: =Assumptions!$B$14 -> 23 | D15: =Assumptions!$B$14 -> 23 | E15: =Assumptions!$B$14 -> 23 | F15: =Assumptions!$B$14 -> 23 | G15: =Assumptions!$B$14 -> 23 | H15: =SUM(B15:G15) -> 138
A16: Net (£) | B16: =B14-B15 -> -22.99325 | C16: =C14-C15 -> -22.948857 | D16: =D14-D15 -> -22.835908 | E16: =E14-E15 -> -22.893971 | F16: =F14-F15 -> -22.856103 | G16: =G14-G15 -> -22.789625 | H16: =SUM(B16:G16) -> -137.31771
A17: Cumulative Amazon orders | B17: =SUM($B$9:B9) -> 0.0108 | C17: =SUM($B$9:C9) -> 0.060696 | D17: =SUM($B$9:D9) -> 0.165996 | E17: =SUM($B$9:E9) -> 0.234036 | F17: =SUM($B$9:F9) -> 0.326376 | G17: =SUM($B$9:G9) -> 0.461376
A20: Base case | B20: =Assumptions!A19 -> Oct 2026 | C20: =Assumptions!A20 -> Nov 2026 | D20: =Assumptions!A21 -> Dec 2026 | E20: =Assumptions!A22 -> Jan 2027 | F20: =Assumptions!A23 -> Feb 2027 | G20: =Assumptions!A24 -> Mar 2027 | H20: Total
A21: Pin impressions | B21: =Assumptions!B19*Assumptions!$C$5 -> 2000 | C21: =Assumptions!B20*Assumptions!$C$5 -> 12000 | D21: =Assumptions!B21*Assumptions!$C$5 -> 30000 | E21: =Assumptions!B22*Assumptions!$C$5 -> 28000 | F21: =Assumptions!B23*Assumptions!$C$5 -> 38000 | G21: =Assumptions!B24*Assumptions!$C$5 -> 50000 | H21: =SUM(B21:G21) -> 160000
A22: Site visits | B22: =B21*Assumptions!$C$6 -> 12 | C22: =C21*Assumptions!$C$6 -> 72 | D22: =D21*Assumptions!$C$6 -> 180 | E22: =E21*Assumptions!$C$6 -> 168 | F22: =F21*Assumptions!$C$6 -> 228 | G22: =G21*Assumptions!$C$6 -> 300 | H22: =SUM(B22:G22) -> 960
A23: Affiliate clicks | B23: =B22*Assumptions!$C$7 -> 3 | C23: =C22*Assumptions!$C$7 -> 18 | D23: =D22*Assumptions!$C$7 -> 45 | E23: =E22*Assumptions!$C$7 -> 42 | F23: =F22*Assumptions!$C$7 -> 57 | G23: =G22*Assumptions!$C$7 -> 75 | H23: =SUM(B23:G23) -> 240
A24: Amazon clicks | B24: =B23*(1-Assumptions!C19) -> 3 | C24: =C23*(1-Assumptions!C20) -> 12.6 | D24: =D23*(1-Assumptions!C21) -> 22.5 | E24: =E23*(1-Assumptions!C22) -> 21 | F24: =F23*(1-Assumptions!C23) -> 28.5 | G24: =G23*(1-Assumptions!C24) -> 37.5 | H24: =SUM(B24:G24) -> 125.1
A25: Amazon orders | B25: =B24*Assumptions!$C$8*Assumptions!D19 -> 0.15 | C25: =C24*Assumptions!$C$8*Assumptions!D20 -> 0.693 | D25: =D24*Assumptions!$C$8*Assumptions!D21 -> 1.4625 | E25: =E24*Assumptions!$C$8*Assumptions!D22 -> 0.945 | F25: =F24*Assumptions!$C$8*Assumptions!D23 -> 1.2825 | G25: =G24*Assumptions!$C$8*Assumptions!D24 -> 1.875 | H25: =SUM(B25:G25) -> 6.408
A26: Amazon commission (£) | B26: =B25*Assumptions!$C$9*Assumptions!$C$10 -> 0.1575 | C26: =C25*Assumptions!$C$9*Assumptions!$C$10 -> 0.72765 | D26: =D25*Assumptions!$C$9*Assumptions!$C$10 -> 1.535625 | E26: =E25*Assumptions!$C$9*Assumptions!$C$10 -> 0.99225 | F26: =F25*Assumptions!$C$9*Assumptions!$C$10 -> 1.346625 | G26: =G25*Assumptions!$C$9*Assumptions!$C$10 -> 1.96875 | H26: =SUM(B26:G26) -> 6.7284
A27: Awin clicks | B27: =B23*Assumptions!C19 -> 0 | C27: =C23*Assumptions!C20 -> 5.4 | D27: =D23*Assumptions!C21 -> 22.5 | E27: =E23*Assumptions!C22 -> 21 | F27: =F23*Assumptions!C23 -> 28.5 | G27: =G23*Assumptions!C24 -> 37.5 | H27: =SUM(B27:G27) -> 114.9
A28: Awin orders | B28: =B27*Assumptions!$C$11*Assumptions!D19 -> 0 | C28: =C27*Assumptions!$C$11*Assumptions!D20 -> 0.1188 | D28: =D27*Assumptions!$C$11*Assumptions!D21 -> 0.585 | E28: =E27*Assumptions!$C$11*Assumptions!D22 -> 0.378 | F28: =F27*Assumptions!$C$11*Assumptions!D23 -> 0.513 | G28: =G27*Assumptions!$C$11*Assumptions!D24 -> 0.75 | H28: =SUM(B28:G28) -> 2.3448
A29: Awin commission (£) | B29: =B28*Assumptions!$C$12*Assumptions!$C$13 -> 0 | C29: =C28*Assumptions!$C$12*Assumptions!$C$13 -> 0.45738 | D29: =D28*Assumptions!$C$12*Assumptions!$C$13 -> 2.25225 | E29: =E28*Assumptions!$C$12*Assumptions!$C$13 -> 1.4553 | F29: =F28*Assumptions!$C$12*Assumptions!$C$13 -> 1.97505 | G29: =G28*Assumptions!$C$12*Assumptions!$C$13 -> 2.8875 | H29: =SUM(B29:G29) -> 9.02748
A30: Total commission (£) | B30: =B26+B29 -> 0.1575 | C30: =C26+C29 -> 1.18503 | D30: =D26+D29 -> 3.787875 | E30: =E26+E29 -> 2.44755 | F30: =F26+F29 -> 3.321675 | G30: =G26+G29 -> 4.85625 | H30: =SUM(B30:G30) -> 15.75588
A31: Tailwind cost (£) | B31: =Assumptions!$C$14 -> 23 | C31: =Assumptions!$C$14 -> 23 | D31: =Assumptions!$C$14 -> 23 | E31: =Assumptions!$C$14 -> 23 | F31: =Assumptions!$C$14 -> 23 | G31: =Assumptions!$C$14 -> 23 | H31: =SUM(B31:G31) -> 138
A32: Net (£) | B32: =B30-B31 -> -22.8425 | C32: =C30-C31 -> -21.81497 | D32: =D30-D31 -> -19.212125 | E32: =E30-E31 -> -20.55245 | F32: =F30-F31 -> -19.678325 | G32: =G30-G31 -> -18.14375 | H32: =SUM(B32:G32) -> -122.24412
A33: Cumulative Amazon orders | B33: =SUM($B$25:B25) -> 0.15 | C33: =SUM($B$25:C25) -> 0.843 | D33: =SUM($B$25:D25) -> 2.3055 | E33: =SUM($B$25:E25) -> 3.2505 | F33: =SUM($B$25:F25) -> 4.533 | G33: =SUM($B$25:G25) -> 6.408
A36: High case | B36: =Assumptions!A19 -> Oct 2026 | C36: =Assumptions!A20 -> Nov 2026 | D36: =Assumptions!A21 -> Dec 2026 | E36: =Assumptions!A22 -> Jan 2027 | F36: =Assumptions!A23 -> Feb 2027 | G36: =Assumptions!A24 -> Mar 2027 | H36: Total
A37: Pin impressions | B37: =Assumptions!B19*Assumptions!$D$5 -> 5000 | C37: =Assumptions!B20*Assumptions!$D$5 -> 30000 | D37: =Assumptions!B21*Assumptions!$D$5 -> 75000 | E37: =Assumptions!B22*Assumptions!$D$5 -> 70000 | F37: =Assumptions!B23*Assumptions!$D$5 -> 95000 | G37: =Assumptions!B24*Assumptions!$D$5 -> 125000 | H37: =SUM(B37:G37) -> 400000
A38: Site visits | B38: =B37*Assumptions!$D$6 -> 50 | C38: =C37*Assumptions!$D$6 -> 300 | D38: =D37*Assumptions!$D$6 -> 750 | E38: =E37*Assumptions!$D$6 -> 700 | F38: =F37*Assumptions!$D$6 -> 950 | G38: =G37*Assumptions!$D$6 -> 1250 | H38: =SUM(B38:G38) -> 4000
A39: Affiliate clicks | B39: =B38*Assumptions!$D$7 -> 17.5 | C39: =C38*Assumptions!$D$7 -> 105 | D39: =D38*Assumptions!$D$7 -> 262.5 | E39: =E38*Assumptions!$D$7 -> 245 | F39: =F38*Assumptions!$D$7 -> 332.5 | G39: =G38*Assumptions!$D$7 -> 437.5 | H39: =SUM(B39:G39) -> 1400
A40: Amazon clicks | B40: =B39*(1-Assumptions!C19) -> 17.5 | C40: =C39*(1-Assumptions!C20) -> 73.5 | D40: =D39*(1-Assumptions!C21) -> 131.25 | E40: =E39*(1-Assumptions!C22) -> 122.5 | F40: =F39*(1-Assumptions!C23) -> 166.25 | G40: =G39*(1-Assumptions!C24) -> 218.75 | H40: =SUM(B40:G40) -> 729.75
A41: Amazon orders | B41: =B40*Assumptions!$D$8*Assumptions!D19 -> 1.4 | C41: =C40*Assumptions!$D$8*Assumptions!D20 -> 6.468 | D41: =D40*Assumptions!$D$8*Assumptions!D21 -> 13.65 | E41: =E40*Assumptions!$D$8*Assumptions!D22 -> 8.82 | F41: =F40*Assumptions!$D$8*Assumptions!D23 -> 11.97 | G41: =G40*Assumptions!$D$8*Assumptions!D24 -> 17.5 | H41: =SUM(B41:G41) -> 59.808
A42: Amazon commission (£) | B42: =B41*Assumptions!$D$9*Assumptions!$D$10 -> 2.52 | C42: =C41*Assumptions!$D$9*Assumptions!$D$10 -> 11.6424 | D42: =D41*Assumptions!$D$9*Assumptions!$D$10 -> 24.57 | E42: =E41*Assumptions!$D$9*Assumptions!$D$10 -> 15.876 | F42: =F41*Assumptions!$D$9*Assumptions!$D$10 -> 21.546 | G42: =G41*Assumptions!$D$9*Assumptions!$D$10 -> 31.5 | H42: =SUM(B42:G42) -> 107.6544
A43: Awin clicks | B43: =B39*Assumptions!C19 -> 0 | C43: =C39*Assumptions!C20 -> 31.5 | D43: =D39*Assumptions!C21 -> 131.25 | E43: =E39*Assumptions!C22 -> 122.5 | F43: =F39*Assumptions!C23 -> 166.25 | G43: =G39*Assumptions!C24 -> 218.75 | H43: =SUM(B43:G43) -> 670.25
A44: Awin orders | B44: =B43*Assumptions!$D$11*Assumptions!D19 -> 0 | C44: =C43*Assumptions!$D$11*Assumptions!D20 -> 1.0395 | D44: =D43*Assumptions!$D$11*Assumptions!D21 -> 5.11875 | E44: =E43*Assumptions!$D$11*Assumptions!D22 -> 3.3075 | F44: =F43*Assumptions!$D$11*Assumptions!D23 -> 4.48875 | G44: =G43*Assumptions!$D$11*Assumptions!D24 -> 6.5625 | H44: =SUM(B44:G44) -> 20.517
A45: Awin commission (£) | B45: =B44*Assumptions!$D$12*Assumptions!$D$13 -> 0 | C45: =C44*Assumptions!$D$12*Assumptions!$D$13 -> 7.016625 | D45: =D44*Assumptions!$D$12*Assumptions!$D$13 -> 34.551563 | E45: =E44*Assumptions!$D$12*Assumptions!$D$13 -> 22.325625 | F45: =F44*Assumptions!$D$12*Assumptions!$D$13 -> 30.299063 | G45: =G44*Assumptions!$D$12*Assumptions!$D$13 -> 44.296875 | H45: =SUM(B45:G45) -> 138.48975
...
